wandb: Currently logged in as: joschka (nextaids). Use `wandb login --relogin` to force relogin
wandb: wandb version 0.13.10 is available!  To upgrade, please run:
wandb:  $ pip install wandb --upgrade
wandb: Tracking run with wandb version 0.13.5
wandb: Run data is saved locally in /home/jgross/kinodata-docked-rescore/wandb/run-20230219_145642-3vbimwb0
wandb: Run `wandb offline` to turn off syncing.
wandb: Syncing run fast-paper-41
wandb: ⭐️ View project at https://wandb.ai/nextaids/kinodata-docked-rescore
wandb: 🚀 View run at https://wandb.ai/nextaids/kinodata-docked-rescore/runs/3vbimwb0
/main/home/mambaforge/lib/python3.9/site-packages/pytorch_lightning/loggers/wandb.py:285: UserWarning: Providing log_model=all requires wandb version >= 0.10.22 for logging associated model metadata.
Hint: Upgrade with `pip install --upgrade wandb`.
  rank_zero_warn(
/main/home/mambaforge/lib/python3.9/site-packages/torch_geometric/data/dataset.py:158: UserWarning: The `pre_filter` argument differs from the one used in the pre-processed version of this dataset. If you want to make use of another pre-fitering technique, make sure to delete '{self.processed_dir}' first
  warnings.warn(
Traceback (most recent call last):
  File "/main/home/mambaforge/lib/python3.9/site-packages/wandb/sdk/wandb_config.py", line 159, in __getattr__
    return self.__getitem__(key)
  File "/main/home/mambaforge/lib/python3.9/site-packages/wandb/sdk/wandb_config.py", line 126, in __getitem__
    return self._items[key]
KeyError: 'checkpoint'

The above exception was the direct cause of the following exception:

Traceback (most recent call last):
  File "/home/jgross/kinodata-docked-rescore/train_regressor.py", line 110, in <module>
    train_regressor(wandb.config)
  File "/home/jgross/kinodata-docked-rescore/train_regressor.py", line 89, in train_regressor
    model = make_model(node_types, edge_types, config)
  File "/home/jgross/kinodata-docked-rescore/train_regressor.py", line 32, in make_model
    if config.checkpoint is not None:
  File "/main/home/mambaforge/lib/python3.9/site-packages/wandb/sdk/wandb_config.py", line 161, in __getattr__
    raise AttributeError(
AttributeError: '<class 'wandb.sdk.wandb_config.Config'>' object has no attribute 'checkpoint'
wandb: Waiting for W&B process to finish... (failed 1). Press Control-C to abort syncing.
wandb: - 0.028 MB of 0.028 MB uploaded (0.000 MB deduped)wandb: \ 0.028 MB of 0.031 MB uploaded (0.000 MB deduped)wandb: | 0.033 MB of 0.033 MB uploaded (0.000 MB deduped)wandb: Synced fast-paper-41: https://wandb.ai/nextaids/kinodata-docked-rescore/runs/3vbimwb0
wandb: Synced 5 W&B file(s), 0 media file(s), 0 artifact file(s) and 0 other file(s)
wandb: Find logs at: ./wandb/run-20230219_145642-3vbimwb0/logs
